Workbook

Sheet 作业说明
A1: 运动服产品生命周期评价（LCA）练习
A3: 项目 | B3: 内容
A4: 功能单位 | B4: 1件运动上衣A。上游中间产品分别以1 kg纱线A、1 kg面料A为功能单位核算。
A5: 系统边界 | B5: T3纱线生产 → T2面料生产 → T1成衣生产 → 产品运输 → 使用维护 → 服装处理。
A6: 数据说明 | B6: 本作业基于真实供应链LCA模型结构进行匿名化和教学化处理。企业名称、产品编号、供应商、地点及部分活动数据已调整。
A7: 主要任务 | B7: 1）在Ecoinvent中查询指定活动对应的数据集；2）填写Dataset、Geography、Reference product、Unit和环境影响因子；3）完成T3、T2、T1及全生命周期GWP计算；4）比较各阶段贡献。
A8: 模型嵌套 | B8: T3纱线A的核算结果直接作为T2纱线输入的碳足迹因子；T2面料A的核算结果直接作为T1面料输入的碳足迹因子，避免重复查询和重复计算。
A9: 单位 | B9: GWP统一为 kg CO2e；运输活动数据为 t·km。请特别注意Ecoinvent数据集的参考单位。
A10: 提交建议 | B10: 保留数据库查询依据，将每一个活动数据对应的影响因子完整信息列出来。独立思考对结果进行解释，简要说明主要排放来源及至少1项数据选择或模型假设带来的不确定性。
A12: 本次模型补充 | B12: 采用模板运动上衣A，保留原始生产活动数量。补充因子、嵌套公式、销售与洗涤情景及消费后包装处理。生产用水量未给，不另加估算。净重0.255kg基于毛投入减边角料的假设；另计算0.310kg名义质量的口径敏感性。
A13: 数据与方法 | B13: ecoinvent 3.12，Cut-off；IPCC 2021 GWP100，climate change: total (excl. biogenic CO2)。原始因子、UUID、LCIA单元格及所有模型参数均列于环境影响因子查询表。
A14: 边界与局限 | B14: 材料优先采用厂门生产过程，模板运输另计。未给出的生产用水量不另估算；T2污水仅覆盖给定药剂与综合电力，直接CH4/N2O及设施缺数据，可能低估。未单列消费者专程购物出行、洗衣机制造和厂房设备。背景数据库自带的用水及基础设施影响仍保留。

Sheet 环境影响因子查询表
A1: 活动类型 | B1: 建议检索关键词 | C1: ecoinvent dataset | D1: Geography | E1: Reference product | F1: Unit | G1: 环境影响因子 | H1: 选择依据 | I1: 数据库参考单位 | J1: 原始GWP100 | K1: 每模型单位对应参考量 | L1: 来源位置（LCIA工作表） | M1: Activity UUID_Product UUID | N1: 查询入口 | O1: 参考产品量（原始符号）
A2: 再生聚酯纤维 | B2: recycled polyester fibre | C2: 组合代理：再生PET粒料 + 中国电力 + 纤维加工损耗 | D2: CN-ZJ / CN | E2: 再生聚酯纤维（模型产物） | F2: kg | G2: =G24/B41+B42*G7+(1/B41-1)*G9 -> 2.531029 | H2: 未找到直接匹配的再生成品纤维条目。粒料投入=1/95%，补入1.5kWh/kg纤维加工电力；加工损耗按cut-off移交。该因子为模型结果，非数据库原值。 | L2: 组合计算；原始数据见第24、7、9行
A3: 聚酯/改性聚酯纤维 | B3: polyester fibre | C3: polyester fibre production, finished | D3: RoW | E3: fibre, polyester | F3: kg | G3: =J3*K3 -> 4.7808263 | H3: RoW普通聚酯纤维生产代理阳离子改性聚酯；改性工序未知。采用厂门生产过程，模板运输另计。 | I3: kg | J3: 4.7808263 | K3: 1 | L3: Cut-off Cumulative LCIA v3.12.xlsx；LCIA!KT19564 | M3: bf221663-baa6-57d5-a675-0446f29bcc46_2fca690e-d8ae-4b9b-8c48-8f658b6e7268 | N3: https://ecoquery.ecoinvent.org/3.12/cutoff/files | O3: 1
A4: 纸质包装材料 | B4: corrugated board / paperboard | C4: corrugated board box production | D4: RoW | E4: corrugated board box | F4: kg | G4: =J4*K4 -> 1.234471 | H4: 纸管、纸箱统一用瓦楞纸箱生产代理；采用生产过程，模板运输另计。 | I4: kg | J4: 1.234471 | K4: 1 | L4: Cut-off Cumulative LCIA v3.12.xlsx；LCIA!KT2462 | M4: e45b56e4-029f-55ba-bc24-eb19aa4bded4_ca213807-7c00-4537-ac8c-23d39d0f2bd5 | N4: https://ecoquery.ecoinvent.org/3.12/cutoff/files | O4: 1
A5: PE包装膜 | B5: polyethylene film / LDPE | C5: packaging film production, low density polyethylene | D5: RoW | E5: packaging film, low density polyethylene | F5: kg | G5: =J5*K5 -> 3.5072778 | H5: LDPE薄膜生产，含制膜；模板运输另计。 | I5: kg | J5: 3.5072778 | K5: 1 | L5: Cut-off Cumulative LCIA v3.12.xlsx；LCIA!KT18796 | M5: 26f9429b-1c81-5698-b8e3-6e99e7c6a4a4_3ce1a817-4ae8-4edc-bf8b-cb1b5d853410 | N5: https://ecoquery.ecoinvent.org/3.12/cutoff/files | O5: 1
A6: 公路货运 | B6: freight transport, lorry | C6: transport, freight, lorry, 16-32 metric ton, diesel, EURO 5 | D6: RoW | E6: transport, freight, lorry, 16-32 metric ton, diesel, EURO 5 | F6: t*km | G6: =J6*K6 -> 0.20208125 | H6: 16–32吨EURO 5柴油货车，RoW代理；t·km与metric ton*km等价。 | I6: metric ton*km | J6: 0.20208125 | K6: 1 | L6: Cut-off Cumulative LCIA v3.12.xlsx；LCIA!KT21666 | M6: 5a2a02ec-1a46-5057-b50c-62bf97de084d_f4e8b38b-d6c7-423b-bc9c-13b4a13d55f8 | N6: https://ecoquery.ecoinvent.org/3.12/cutoff/files | O6: 1
A7: 电力 | B7: electricity, medium voltage | C7: market group for electricity, medium voltage | D7: CN | E7: electricity, medium voltage | F7: kWh | G7: =J7*K7 -> 0.85419415 | H7: 生产用中国中压电力，含电网供应链。 | I7: kWh | J7: 0.85419415 | K7: 1 | L7: Cut-off Cumulative LCIA v3.12.xlsx；LCIA!KT17325 | M7: 64d70fe5-a32d-52a9-8901-3b52f9e4ab4e_759b89bd-3aa6-42ad-b767-5bb9ef5d331d | N7: https://ecoquery.ecoinvent.org/3.12/cutoff/files | O7: 1
A8: 柴油 | B8: diesel | C8: diesel, burned in building machine | D8: GLO | E8: diesel, burned in building machine | F8: kg | G8: =J8*K8 -> 4.2880993 | H8: 叉车以工程机械柴油燃烧代理，含燃料上游及燃烧；42.6 MJ/kg。 | I8: MJ | J8: 0.10065961 | K8: =B43 -> 42.6 | L8: Cut-off Cumulative LCIA v3.12.xlsx；LCIA!KT2626 | M8: 4d495ac1-a2a2-58b9-ada2-23d5c1da15c1_b0f4c2fb-5081-474a-8ffa-1457da8345db | N8: https://ecoquery.ecoinvent.org/3.12/cutoff/files | O8: 1
A9: 纺织废料回收/处理 | B9: waste textile treatment | C9: fibre and fabric waste, polyester, Recycled Content cut-off | D9: GLO | E9: fibre and fabric waste, polyester | F9: kg | G9: =J9*K9 -> 0 | H9: 可回收废纺织物在产生端按cut-off移交，后续再生加工归下一生命周期；不计避免原生料抵扣。混合可回收固废亦按此边界。 | I9: kg | J9: 0 | K9: 1 | L9: Cut-off Cumulative LCIA v3.12.xlsx；LCIA!KT6112 | M9: ac755a40-ef4e-56ac-a70e-e1fbcb37ed2b_c4e028dc-33a3-4fb1-b0d7-08d0d1242d71 | N9: https://support.ecoinvent.org/system-models | O9: 1
A10: 碳酸钠 | B10: sodium carbonate | C10: soda ash production, dense, Hou's process | D10: GLO | E10: soda ash, dense | F10: kg | G10: =J10*K10 -> 1.1841768 | H10: 重质纯碱采用侯氏制碱生产过程；选取纯碱参考产品，未选副产氯化铵。模板运输另计。 | I10: kg | J10: 1.1841768 | K10: 1 | L10: Cut-off Cumulative LCIA v3.12.xlsx；LCIA!KT20528 | M10: f1ac1aa8-65df-5298-87e7-a8f1924e1699_278cf104-dd4f-4dc9-8160-cdc97d2da7a2 | N10: https://ecoquery.ecoinvent.org/3.12/cutoff/files | O10: 1
A11: 硫酸钠 | B11: sodium sulfate | C11: sodium sulfate production, from natural sources | D11: RoW | E11: sodium sulfate, anhydrite | F11: kg | G11: =J11*K11 -> 0.17425084 | H11: RoW天然矿物法无水硫酸钠生产代理；工艺未经企业核实，不能视为中国实际工艺。模板运输另计。 | I11: kg | J11: 0.17425084 | K11: 1 | L11: Cut-off Cumulative LCIA v3.12.xlsx；LCIA!KT20628 | M11: f2ad1295-9ee9-5d6b-a264-d3e135b45d36_2cfef82e-cb0d-4864-8163-9651fc6c25eb | N11: https://ecoquery.ecoinvent.org/3.12/cutoff/files | O11: 1
A12: 染整助剂 | B12: textile chemical / organic chemical | C12: chemical production, organic, unspecified | D12: GLO | E12: chemical, organic, unspecified | F12: kg | G12: =J12*K12 -> 3.8774584 | H12: 专用助剂成分不详，用未指定有机化学品生产代理；显著技术不确定性。模板运输另计。 | I12: kg | J12: 3.8774584 | K12: 1 | L12: Cut-off Cumulative LCIA v3.12.xlsx；LCIA!KT1622 | M12: 73a1c1d2-45f0-595d-b7a7-ef3672f17888_30af3aa9-941d-5cc4-8985-e6323ca567d1 | N12: https://ecoquery.ecoinvent.org/3.12/cutoff/files | O12: 1
A13: 分散染料 | B13: dye / organic chemical | C13: chemical production, organic, aromatics | D13: GLO | E13: chemical, organic, aromatics | F13: kg | G13: =J13*K13 -> 3.5487324 | H13: 无分散染料配方，以芳香族有机化学品生产代理，不另加染整过程。模板运输另计。 | I13: kg | J13: 3.5487324 | K13: 1 | L13: Cut-off Cumulative LCIA v3.12.xlsx；LCIA!KT1618 | M13: 26984de7-6e7a-5995-b208-5f7c6babb31b_8d8cff2b-d2cd-443a-af08-1e103254c5c2 | N13: https://ecoquery.ecoinvent.org/3.12/cutoff/files | O13: 1
A14: 外购蒸汽 | B14: steam | C14: steam production, in chemical industry | D14: RoW | E14: steam, in chemical industry | F14: kg | G14: =J14*K14 -> 0.34589816 | H14: 外购蒸汽采用生产过程，参考单位为kg；不再把同一蒸汽另算燃气。 | I14: kg | J14: 0.34589816 | K14: 1 | L14: Cut-off Cumulative LCIA v3.12.xlsx；LCIA!KT20869 | M14: 2cead54a-df60-5734-9177-0794444b57e4_bd20be8e-9b7a-4391-980f-4ecf8f2867be | N14: https://ecoquery.ecoinvent.org/3.12/cutoff/files | O14: 1
A15: 天然气 | B15: natural gas | C15: heat production, natural gas, at boiler condensing modulating >100kW | D15: RoW | E15: heat, district or industrial, natural gas | F15: m3 | G15: =J15*K15 -> 2.2292428 | H15: 燃气视为独立现场锅炉用气，含供应与燃烧；35.8 MJ/m3×90%供热效率。 | I15: MJ | J15: 0.069188168 | K15: =B44*B45 -> 32.22 | L15: Cut-off Cumulative LCIA v3.12.xlsx；LCIA!KT7637 | M15: eb3c4b4b-2ed5-5d0f-a01f-b282fdf8f054_1125e767-7b5d-442e-81d6-9b0d3e1919ac | N15: https://ecoquery.ecoinvent.org/3.12/cutoff/files | O15: 1
A16: 氢氧化钠 | B16: sodium hydroxide | C16: chlor-alkali electrolysis, membrane cell | D16: RoW | E16: sodium hydroxide, without water, in 50% solution state | F16: kg | G16: =J16*K16 -> 1.4827763 | H16: RoW膜法氯碱生产；基准把模板质量视为NaOH有效物质，若是50%商品溶液，B47改0.5。模板运输另计。 | I16: kg | J16: 1.4827763 | K16: =B47 -> 1 | L16: Cut-off Cumulative LCIA v3.12.xlsx；LCIA!KT1652 | M16: 6fcd5f7d-ee46-5a34-9f18-e73d554020be_61396bcb-bf35-411a-a6a6-8543ccef83e8 | N16: https://ecoquery.ecoinvent.org/3.12/cutoff/files | O16: 1
A17: 聚合氯化铝 | B17: aluminium chloride / water treatment chemical | C17: polyaluminium chloride production | D17: GLO | E17: polyaluminium chloride | F17: kg | G17: =J17*K17 -> 1.5725731 | H17: 聚合氯化铝生产，未用普通氯化铝替代。模板运输另计。 | I17: kg | J17: 1.5725731 | K17: 1 | L17: Cut-off Cumulative LCIA v3.12.xlsx；LCIA!KT19540 | M17: 01f243a8-747d-5726-a5a9-bd8047b5a14c_f2482f81-8982-531b-8e49-ffa38a6f01eb | N17: https://ecoquery.ecoinvent.org/3.12/cutoff/files | O17: 1
A18: 次氯酸钠 | B18: sodium hypochlorite | C18: chlor-alkali electrolysis, membrane cell | D18: RoW | E18: sodium hypochlorite, without water, in 15% solution state | F18: kg | G18: =J18*K18 -> 2.6394971 | H18: RoW膜法氯碱生产；基准把模板质量视为NaClO有效物质，若为15%商品溶液，B48改0.15。模板运输另计。 | I18: kg | J18: 2.6394971 | K18: =B48 -> 1 | L18: Cut-off Cumulative LCIA v3.12.xlsx；LCIA!KT1653 | M18: 6fcd5f7d-ee46-5a34-9f18-e73d554020be_96501bb6-a68f-41f5-a067-92137e816e05 | N18: https://ecoquery.ecoinvent.org/3.12/cutoff/files | O18: 1
A19: 废物焚烧 | B19: municipal solid waste incineration / waste incineration | C19: treatment of municipal solid waste, municipal incineration | D19: RoW | E19: municipal solid waste | F19: kg | G19: =J19*K19 -> 0.51899253 | H19: 成分未明的小量焚烧废物用一般固废代理；PET及PE废物另用专属因子。 | I19: kg | J19: 0.51899253 | K19: 1 | L19: Cut-off Cumulative LCIA v3.12.xlsx；LCIA!KT22923 | M19: 618bd0cb-cf51-5a34-9b58-0343c429fbca_27da8130-82ba-485c-a800-b89efdcb0491 | N19: https://ecoquery.ecoinvent.org/3.12/cutoff/files | O19: -1
A20: 自来水 | B20: tap water | C20: market for tap water | D20: RoW | E20: tap water | F20: kg | G20: =J20*K20 -> 0.0011997629 | H20: RoW自来水市场代理中国用水；kg为参考单位。 | I20: kg | J20: 0.0011997629 | K20: 1 | L20: Cut-off Cumulative LCIA v3.12.xlsx；LCIA!KT15717 | M20: ac46debc-ffb4-500f-975b-7b06695fceb5_c5adb1fb-872e-4446-a3bb-c4b61aa4bd45 | N20: https://ecoquery.ecoinvent.org/3.12/cutoff/files | O20: 1
A21: 污水处理 | B21: wastewater treatment | C21: treatment of wastewater, average, wastewater treatment | D21: RoW | E21: wastewater, average | F21: kg | G21: =J21*K21 -> 0.00046757024 | H21: 平均污水处理RoW代理；模型kg按密度1000kg/m3换算。 | I21: m3 | J21: 0.46757024 | K21: =1/B49 -> 0.001 | L21: Cut-off Cumulative LCIA v3.12.xlsx；LCIA!KT25602 | M21: 571c5616-4195-55ca-84e4-db819cbdfdc1_e8a51ec1-60cb-4ead-a948-ad1142c61918 | N21: https://ecoquery.ecoinvent.org/3.12/cutoff/files | O21: -1
A22: 清洁剂 | B22: detergent | C22: market for soap | D22: GLO | E22: soap | F22: kg | G22: =J22*K22 -> 3.9045679 | H22: 清洁剂配方不详，以soap市场代理成品清洁剂，属于成分代理。 | I22: kg | J22: 3.9045679 | K22: 1 | L22: Cut-off Cumulative LCIA v3.12.xlsx；LCIA!KT15333 | M22: b113a26b-9465-59af-9aec-a8e7229c5fdb_3372cdea-bef5-4186-9ae6-b67a016aa67d | N22: https://ecoquery.ecoinvent.org/3.12/cutoff/files | O22: 1
A23: 碳酸氢钠 | B23: sodium bicarbonate | C23: market for sodium bicarbonate | D23: RoW | E23: sodium bicarbonate | F23: kg | G23: =J23*K23 -> 1.2964591 | H23: 填列供参考；活动清单未消耗碳酸氢钠，故不计入总量。 | I23: kg | J23: 1.2964591 | K23: 1 | L23: Cut-off Cumulative LCIA v3.12.xlsx；LCIA!KT15342 | M23: 74e4c205-c419-56a0-85c0-630519e3469f_033be19b-ca83-4d9e-8dd6-476ef15203cd | N23: https://ecoquery.ecoinvent.org/3.12/cutoff/files | O23: 1
A24: 再生PET粒料 | B24: polyethylene terephthalate, pellets, recycled fibre based | C24: treatment of waste polyester, industrial, from textile production, hydrothermal treatment | D24: CN-ZJ | E24: polyethylene terephthalate, pellets, recycled fibre based | F24: kg | G24: =J24*K24 -> 1.1872509 | H24: 浙江工业废聚酯水热回收生产的再生PET粒料；采用粒料参考产品，非废物处置服务。补入纤维加工能耗及损耗，模板运输另计。 | I24: kg | J24: 1.1872509 | K24: 1 | L24: Cut-off Cumulative LCIA v3.12.xlsx；LCIA!KT25198 | M24: c25ec78b-9ec9-5c8d-baf8-50de51f90395_3915d667-f400-4d9b-8e57-9489a1a2fa3b | N24: https://ecoquery.ecoinvent.org/3.12/cutoff/files | O24: 1
A25: 低压电力 | B25: electricity, low voltage | C25: market group for electricity, low voltage | D25: CN | E25: electricity, low voltage | F25: kWh | G25: =J25*K25 -> 0.84737294 | H25: 销售与家庭洗涤用中国低压电力。 | I25: kWh | J25: 0.84737294 | K25: 1 | L25: Cut-off Cumulative LCIA v3.12.xlsx；LCIA!KT17308 | M25: 74de192b-ed0c-5bed-90f1-fb0d1ab51ef0_d69294d7-8d64-4915-a896-9996a014c410 | N25: https://ecoquery.ecoinvent.org/3.12/cutoff/files | O25: 1
A26: PET废物焚烧 | B26: waste polyethylene terephthalate | C26: treatment of waste polyethylene terephthalate, municipal incineration | D26: GLO | E26: waste polyethylene terephthalate | F26: kg | G26: =J26*K26 -> 2.0663911 | H26: 聚酯成衣按PET废物焚烧；选择废物kg的处置服务，未选零负担副产电/热。 | I26: kg | J26: 2.0663911 | K26: 1 | L26: Cut-off Cumulative LCIA v3.12.xlsx；LCIA!KT25213 | M26: 3b4c9c92-d3f6-5a53-82f1-9c160946e760_dcb70fd5-e305-4920-b68b-40697cc6a206 | N26: https://ecoquery.ecoinvent.org/3.12/cutoff/files | O26: -1
A27: PE废物焚烧 | B27: waste polyethylene | C27: treatment of waste polyethylene, municipal incineration | D27: GLO | E27: waste polyethylene | F27: kg | G27: =J27*K27 -> 3.0988962 | H27: PE生产废料及消费后包装按PE废物焚烧。 | I27: kg | J27: 3.0988962 | K27: 1 | L27: Cut-off Cumulative LCIA v3.12.xlsx；LCIA!KT25251 | M27: d7640922-25bf-595a-b031-6f8a3425fb6c_7ee0ddc3-924d-4339-b9bf-7856af6a698f | N27: https://ecoquery.ecoinvent.org/3.12/cutoff/files | O27: -1
A28: 纸板回收移交 | B28: waste paperboard, unsorted | C28: waste paperboard, unsorted, Recycled Content cut-off | D28: GLO | E28: waste paperboard, unsorted | F28: kg | G28: =J28*K28 -> 0 | H28: 纸包装回收在产生端cut-off移交，不计回收替代收益。 | I28: kg | J28: 0 | K28: 1 | L28: Cut-off Cumulative LCIA v3.12.xlsx；LCIA!KT26077 | M28: 0b55e655-d17a-50b1-8f48-2dd4e09142d7_ad38bbd2-e41c-4509-9dc3-c5c708a36606 | N28: https://support.ecoinvent.org/system-models | O28: 1
A29: 其他纺织辅料 | B29: textile, nonwoven polyester | C29: textile production, nonwoven polyester, needle-punched | D29: RoW | E29: textile, nonwoven polyester | F29: kg | G29: =J29*K29 -> 6.1688108 | H29: 其他纺织辅料假设为RoW针刺聚酯无纺材料生产；实际组成未知。模板运输另计。 | I29: kg | J29: 6.1688108 | K29: 1 | L29: Cut-off Cumulative LCIA v3.12.xlsx；LCIA!KT21368 | M29: 4986e004-6a31-5c72-bb07-7cca4000dbac_328db9f7-c0d6-4598-b071-d67dd31974f8 | N29: https://ecoquery.ecoinvent.org/3.12/cutoff/files | O29: 1
A31: 数据库及评价口径 | C31: ecoinvent 3.12；Allocation, cut-off by classification
C32: IPCC 2021 | climate change: total (excl. biogenic CO2) | global warming potential (GWP100)；kg CO2-Eq。查询：2026-10-21。
C33: 原始LCIA列KT；废物参考量-1表示消纳服务，本表原始GWP是处理1kg或1m3的正负影响值，按正的待处理量相乘，不把-1再乘入。
A34: 模型参数 | B34: 取值 | C34: 单位 | H34: 来源与情景解释（均为教学模型假设，非企业实测）
A35: 全寿命洗涤次数 | B35: 100 | C35: 次 | H35: 每次穿着后洗涤，基准100次；自然晾干，不熨烫，不烘干。
A36: 每桶混洗衣物质量 | B36: 2.55 | C36: kg/桶 | H36: 按成衣净质量/每桶衣物质量分摊；基准单件占10%。
A37: 每桶洗衣用水 | B37: 57 | C37: kg/桶 | H37: 含漂洗；使用污水量等于自来水量，忽略衣物残留水。
A38: 每桶洗衣用电 | B38: 0.5 | C38: kWh/桶 | H38: 一次洗衣程序总用电；未再单算热水，避免重复。
A39: 每桶清洁剂用量 | B39: 0.05 | C39: kg/桶 | H39: 成品清洁剂，以soap代理；洗衣机制造及清洁剂包装未单列。
A40: 报废衣物回收比例 | B40: 0.15 | C40: 比例 | H40: 其余85%焚烧；回收为cut-off移交，不计避免负担。
A41: 再生纤维加工质量收率 | B41: 0.95 | C41: 比例 | H41: 粒料至成品纤维加工假设；0.95kg成品/kg粒料。
...

Sheet T3_纱线
A1: 序号 | B1: 环节 | C1: 活动数据 | D1: 数量 | E1: 单位 | F1: 说明 | G1: 因子（kg CO2e/活动单位） | H1: 碳排放（kg CO2e）
A2: 1 | B2: 材料 | C2: 再生聚酯纤维 | D2: 0.77 | E2: kg | G2: =环境影响因子查询表!$G$2 -> 2.531029 | H2: =D2*G2 -> 1.9488923
A3: 2 | B3: 材料 | C3: 阳离子改性聚酯纤维 | D3: 0.29 | E3: kg | G3: =环境影响因子查询表!$G$3 -> 4.7808263 | H3: =D3*G3 -> 1.3864396
A4: 3 | B4: 材料 | C4: 纸质包装材料 | D4: 0.05 | E4: kg | F4: 纸管和纸箱的加总 | G4: =环境影响因子查询表!$G$4 -> 1.234471 | H4: =D4*G4 -> 0.061723551
A5: 4 | B5: 材料 | C5: PE包装膜 | D5: 0.002 | E5: kg | G5: =环境影响因子查询表!$G$5 -> 3.5072778 | H5: =D5*G5 -> 0.0070145557
A6: 5 | B6: 原材料运输 | C6: 原辅材料公路运输 | D6: 0.19 | E6: t*km | F6: 各原辅料运输的总和 | G6: =环境影响因子查询表!$G$6 -> 0.20208125 | H6: =D6*G6 -> 0.038395438
A7: 6 | B7: 能耗 | C7: 纺纱生产用电 | D7: 3.9 | E7: kWh | F7: 含清花、前纺、后纺及公用设施 | G7: =环境影响因子查询表!$G$7 -> 0.85419415 | H7: =D7*G7 -> 3.3313572
A8: 7 | B8: 固废处理 | C8: 纺织废料回收/处理 | D8: 0.06 | E8: kg | G8: =环境影响因子查询表!$G$9 -> 0 | H8: =D8*G8 -> 0
A9: 8 | B9: 厂内运输 | C9: 叉车柴油 | D9: 0.0015 | E9: kg | G9: =环境影响因子查询表!$G$8 -> 4.2880993 | H9: =D9*G9 -> 0.006432149
A11: T3纱线A碳足迹（1 kg纱线A） | H11: =SUM(H2:H9) -> 6.7802548

Sheet T2_面料
A1: 序号 | B1: 目录 | C1: 活动数据 | D1: 数量 | E1: 单位 | F1: 说明 | G1: 因子（kg CO2e/活动单位） | H1: 碳排放（kg CO2e）
A2: 1 | B2: 材料 | C2: 纱线A（来自T3） | D2: 1.08 | E2: kg | F2: GWP因子直接引用T3计算结果 | G2: =T3_纱线!H11 -> 6.7802548 | H2: =D2*G2 -> 7.3226752
A3: 2 | B3: 材料 | C3: 碳酸钠 | D3: 0.03 | E3: kg | G3: =环境影响因子查询表!$G$10 -> 1.1841768 | H3: =D3*G3 -> 0.035525305
A4: 3 | B4: 材料 | C4: 硫酸钠 | D4: 0.02 | E4: kg | G4: =环境影响因子查询表!$G$11 -> 0.17425084 | H4: =D4*G4 -> 0.0034850168
A5: 4 | B5: 材料 | C5: 染整助剂 | D5: 0.15 | E5: kg | F5: 由多种专用助剂加总 | G5: =环境影响因子查询表!$G$12 -> 3.8774584 | H5: =D5*G5 -> 0.58161875
A6: 5 | B6: 材料 | C6: 分散染料 | D6: 0.014 | E6: kg | F6: 由多种染料加总 | G6: =环境影响因子查询表!$G$13 -> 3.5487324 | H6: =D6*G6 -> 0.049682253
A7: 6 | B7: 材料 | C7: PE包装膜 | D7: 0.006 | E7: kg | G7: =环境影响因子查询表!$G$5 -> 3.5072778 | H7: =D7*G7 -> 0.021043667
A8: 7 | B8: 材料 | C8: 纸管 | D8: 0.019 | E8: kg | G8: =环境影响因子查询表!$G$4 -> 1.234471 | H8: =D8*G8 -> 0.023454949
A9: 8 | B9: 原材料运输 | C9: 原辅材料公路运输 | D9: 0.07 | E9: t*km | F9: 各供应商运输加总 | G9: =环境影响因子查询表!$G$6 -> 0.20208125 | H9: =D9*G9 -> 0.014145688
A10: 9 | B10: 能耗 | C10: 生产用电 | D10: 4.8 | E10: kWh | G10: =环境影响因子查询表!$G$7 -> 0.85419415 | H10: =D10*G10 -> 4.1001319
A11: 10 | B11: 能耗 | C11: 外购蒸汽 | D11: 10.5 | E11: kg | G11: =环境影响因子查询表!$G$14 -> 0.34589816 | H11: =D11*G11 -> 3.6319307
A12: 11 | B12: 能耗 | C12: 天然气 | D12: 0.8 | E12: m3 | F12: 独立现场锅炉用气；假设不与外购蒸汽重叠。若实际上仅用于生成已列蒸汽，应删去重复项。 | G12: =环境影响因子查询表!$G$15 -> 2.2292428 | H12: =D12*G12 -> 1.7833942
A13: 12 | B13: 污水处理 | C13: 氢氧化钠 | D13: 0.14 | E13: kg | G13: =环境影响因子查询表!$G$16 -> 1.4827763 | H13: =D13*G13 -> 0.20758869
A14: 13 | B14: 污水处理 | C14: 聚合氯化铝 | D14: 0.16 | E14: kg | G14: =环境影响因子查询表!$G$17 -> 1.5725731 | H14: =D14*G14 -> 0.2516117
A15: 14 | B15: 污水处理 | C15: 次氯酸钠 | D15: 0.014 | E15: kg | G15: =环境影响因子查询表!$G$18 -> 2.6394971 | H15: =D15*G15 -> 0.03695296
A16: 15 | B16: 固废处理 | C16: 可回收固废 | D16: 0.145 | E16: kg | F16: 纺织、纸、塑料等可回收固废加总 | G16: =环境影响因子查询表!$G$9 -> 0 | H16: =D16*G16 -> 0
A17: 16 | B17: 固废处理 | C17: 焚烧处置废物 | D17: 0.004 | E17: kg | G17: =环境影响因子查询表!$G$19 -> 0.51899253 | H17: =D17*G17 -> 0.0020759701
A19: T2面料A碳足迹（1 kg面料A） | H19: =SUM(H2:H17) -> 18.065317

Sheet T1_成衣
A1: 序号 | B1: 目录 | C1: 活动数据 | D1: 数量 | E1: 单位 | F1: 说明 | G1: 因子（kg CO2e/活动单位） | H1: 碳排放（kg CO2e）
A2: 1 | B2: 材料 | C2: 面料A（来自T2） | D2: 0.235 | E2: kg | F2: GWP因子直接引用T2计算结果 | G2: =T2_面料!H19 -> 18.065317 | H2: =D2*G2 -> 4.2453495
A3: 2 | B3: 材料 | C3: 第二种聚酯面料 | D3: 0.01 | E3: kg | F3: 第二种聚酯面料按同类T2面料代理。 | G3: =T2_面料!H19 -> 18.065317 | H3: =D3*G3 -> 0.18065317
A4: 3 | B4: 材料 | C4: 聚酯缝纫线 | D4: 0.027 | E4: kg | F4: 缝纫线按T3纱线代理，未另加专门捻线/润滑工序；保留模板27g/件，质量口径未核实。 | G4: =T3_纱线!H11 -> 6.7802548 | H4: =D4*G4 -> 0.18306688
A5: 4 | B5: 材料 | C5: 其他纺织辅料 | D5: 0.038 | E5: kg | F5: 其他辅料按聚酯无纺材料代理，真实成分未知。 | G5: =环境影响因子查询表!$G$29 -> 6.1688108 | H5: =D5*G5 -> 0.23441481
A6: 5 | B6: 材料 | C6: PE包装膜 | D6: 0.007 | E6: kg | G6: =环境影响因子查询表!$G$5 -> 3.5072778 | H6: =D6*G6 -> 0.024550945
A7: 6 | B7: 材料 | C7: 纸质包装 | D7: 0.032 | E7: kg | G7: =环境影响因子查询表!$G$4 -> 1.234471 | H7: =D7*G7 -> 0.039503072
A8: 7 | B8: 原材料运输 | C8: 原辅材料公路运输 | D8: 0.011 | E8: t*km | F8: 各供应商运输聚合 | G8: =环境影响因子查询表!$G$6 -> 0.20208125 | H8: =D8*G8 -> 0.0022228938
A9: 8 | B9: 能耗 | C9: 成衣生产用电 | D9: 0.29 | E9: kWh | F9: 含厂内运输、裁剪、缝纫、整烫、包装、绣花及公用设施 | G9: =环境影响因子查询表!$G$7 -> 0.85419415 | H9: =D9*G9 -> 0.2477163
A10: 9 | B10: 污水处理 | C10: 污水/再生水处理 | D10: 16 | E10: kg | G10: =环境影响因子查询表!$G$21 -> 0.00046757024 | H10: =D10*G10 -> 0.0074811238
A11: 10 | B11: 固废处理 | C11: 纺织边角料 | D11: 0.055 | E11: kg | G11: =环境影响因子查询表!$G$9 -> 0 | H11: =D11*G11 -> 0
A12: 11 | B12: 固废处理 | C12: 塑料废弃物 | D12: 0.003 | E12: kg | F12: 简化为统一处置口径 | G12: =环境影响因子查询表!$G$27 -> 3.0988962 | H12: =D12*G12 -> 0.0092966887
A13: 12 | B13: 固废处理 | C13: 纸类废弃物 | D13: 0.009 | E13: kg | F13: 简化为回收/处理口径 | G13: =环境影响因子查询表!$G$28 -> 0 | H13: =D13*G13 -> 0
A14: 13 | B14: 固废处理 | C14: 固废外运 | D14: 0.006 | E14: t*km | G14: =环境影响因子查询表!$G$6 -> 0.20208125 | H14: =D14*G14 -> 0.0012124875
A15: 14 | B15: 产品运输 | C15: 成衣公路运输 | D15: 0.6 | E15: t*km | F15: 教学情景假设，不代表实际运输路线 | G15: =环境影响因子查询表!$G$6 -> 0.20208125 | H15: =D15*G15 -> 0.12124875
A16: 15 | B16: 产品销售 | C16: 销售与仓储分摊电力 | D16: =环境影响因子查询表!$B$46 -> 0.1 | E16: kWh | F16: 线上销售情景；产品运输已在上一行单列，不另加消费者出行。 | G16: =环境影响因子查询表!$G$25 -> 0.84737294 | H16: =D16*G16 -> 0.084737294
A17: 16 | B17: 使用维护 | C17: 洗涤用电 | D17: =环境影响因子查询表!$B$35*$D$29/环境影响因子查询表!$B$36*环境影响因子查询表!$B$38 -> 5 | E17: kWh | F17: 100次混洗，单件/每桶衣物质量分摊；参数见因子表第35–39行；自然晾干。 | G17: =环境影响因子查询表!$G$25 -> 0.84737294 | H17: =D17*G17 -> 4.2368647
A18: 17 | B18: 使用维护 | C18: 洗涤自来水 | D18: =环境影响因子查询表!$B$35*$D$29/环境影响因子查询表!$B$36*环境影响因子查询表!$B$37 -> 570 | E18: kg | F18: 100次混洗，单件/每桶衣物质量分摊；参数见因子表第35–39行；自然晾干。 | G18: =环境影响因子查询表!$G$20 -> 0.0011997629 | H18: =D18*G18 -> 0.68386484
A19: 18 | B19: 使用维护 | C19: 洗涤清洁剂 | D19: =环境影响因子查询表!$B$35*$D$29/环境影响因子查询表!$B$36*环境影响因子查询表!$B$39 -> 0.5 | E19: kg | F19: 100次混洗，单件/每桶衣物质量分摊；参数见因子表第35–39行；自然晾干。 | G19: =环境影响因子查询表!$G$22 -> 3.9045679 | H19: =D19*G19 -> 1.952284
A20: 19 | B20: 使用维护 | C20: 污水处理 | D20: =D18 -> 570 | E20: kg | F20: 洗涤污水与用水等量；基准为570kg，对应0.570m3。 | G20: =环境影响因子查询表!$G$21 -> 0.00046757024 | H20: =D20*G20 -> 0.26651504
A21: 20 | B21: 服装处理 | C21: 降级回收 | D21: =$D$29*环境影响因子查询表!$B$40 -> 0.03825 | E21: kg | F21: 净质量×15%，按cut-off移交，不给回收抵扣。 | G21: =环境影响因子查询表!$G$9 -> 0 | H21: =D21*G21 -> 0
A22: 21 | B22: 服装处理 | C22: 焚烧 | D22: =$D$29*(1-环境影响因子查询表!$B$40) -> 0.21675 | E22: kg | F22: 净质量×85%，采用PET专属焚烧处置因子。 | G22: =环境影响因子查询表!$G$26 -> 2.0663911 | H22: =D22*G22 -> 0.44789027
A24: 1件运动上衣A全生命周期GWP | H24: =SUM(H2:H22,H26:H27) -> 12.981268
C26: 消费后PE包装焚烧 | D26: =D6-D12 -> 0.004 | E26: kg | F26: PE投入减生产废料，剩余随成衣交付消费者；全量焚烧。 | G26: =环境影响因子查询表!$G$27 -> 3.0988962 | H26: =D26*G26 -> 0.012395585
C27: 消费后纸包装回收 | D27: =D7-D13 -> 0.023 | E27: kg | F27: 纸包装投入减生产废料；按cut-off移交。 | G27: =环境影响因子查询表!$G$28 -> 0 | H27: =D27*G27 -> 0
C29: 成衣净质量（假设） | D29: =SUM(D2:D5)-D11 -> 0.255 | E29: kg | F29: 假设模板材料量为含边角损耗的毛投入：0.310−0.055=0.255kg，不含包装。不是已核实的实测净重。
C30: 原模板报废质量 | D30: 0.31 | E30: kg | F30: 保留原始0.047+0.263kg作对照。若材料数据本身已扣损耗，应重新核实净质量。

Sheet 结果汇总
A1: 阶段 | B1: 碳排放（kg CO2e）
A2: T3 纱线A（1 kg，中间产品结果） | B2: =T3_纱线!H11 -> 6.7802548 | C2: 中间结果；不可与总量直接相加
A3: T2 面料A（1 kg，中间产品结果） | B3: =T2_面料!H19 -> 18.065317 | C3: 中间结果；已嵌入成衣
A4: 1件运动上衣A 全生命周期 | B4: =T1_成衣!H24 -> 12.981268 | C4: ="1件；净重假设"&TEXT(T1_成衣!D29,"0.000")&"kg；洗涤"&TEXT(环境影响因子查询表!$B$35,"0")&"次" -> 1件；净重假设0.255kg；洗涤100次
A5: 生产环节（T3至T1合计） | B5: =SUM(B29:B31) -> 5.1754679 | C5: 含原料、加工和厂际运输；kg CO2e/件
A7: 结果解释、主要排放来源与不确定性
A8: ="本情景以1件运动上衣A为功能单位，全生命周期GWP为 "&TEXT(B4,"0.00")&" kg CO2e/件。阶段分解中，"&INDEX(A29:A35,MATCH(MAX(B29:B35),B29:B35,0))&"贡献最高，占 "&TEXT(MAX(C29:C35),"0.0%")&"。主面料的纱线和面料加工合计为 "&TEXT(SUM(B29:B30),"0.00")&" kg CO2e；其他外购面料和缝纫线的上游影响归入T1其他材料，未与主面料阶段重复相加。"&CHAR(10)&CHAR(10)&"生产端重点是电力、蒸汽以及聚酯原料，使用端重点是洗涤用电和清洁剂。减少非必要洗涤、提高洗衣装载率、自然晾干，以及降低生产电耗和蒸汽需求，均可能减排。"&CHAR(10)&CHAR(10)&"不确定性1：使用假设为100次混洗，每桶2.55kg、57kg水、0.5kWh电和0.05kg清洁剂，按质量分摊。若洗涤50次或150次，其余参数不变，总量分别为 "&TEXT(C41,"0.00")&" 与 "&TEXT(C43,"0.00")&" kg CO2e。所以，作为单因素的情景，这里不能视为统计置信区间。"&CHAR(10)&CHAR(10)&"不确定性2：再生纤维采用浙江再生PET粒料加加工电力的组合代理，收率95%、电耗1.5kWh/kg；但是没有掌握具体纺丝技术和辅料。电耗0.75至3kWh/kg时，总量为 "&TEXT(B48,"0.00")&" 至 "&TEXT(B50,"0.00")&" kg CO2e。"&CHAR(10)&CHAR(10)&"不确定性3：染料、助剂、清洁剂及部分辅料使用类别代理，RoW/GLO数据不一定代表中国的实际供应链。NaOH与NaClO基准按有效物质质量，若原数据是商品溶液则会高估用量。生产用水量未给、无法另外估算；T2污水直接排放和部分设施缺数据，可能低估数据。材料改用生产过程并另计模板运输，保留了背景上游物流。"&CHAR(10)&CHAR(10)&"质量口径假设：把0.310kg材料量视为含损耗毛投入，减少0.055kg边角料，净重0.255kg，报废回收0.03825kg、焚烧0.21675kg。该口径没有进行实测核实。保留原模板0.310kg的名义质量、仅调整洗涤和报废时，总量为 "&TEXT(C55,"0.00")&" kg CO2e；生产清单保持不变。回收按cut-off移交，不能保证避免原生料可信，计算结果上零负担，但不代表着现实回收零排放。" -> 本情景以1件运动上衣A为功能单位，全生命周期GWP为 12.98 kg CO2e/件。阶段分解中，使用维护贡献最高，占 55.0%。主面料的纱线和面料加工合计为 4.25 kg CO2e；其他外购面料和缝纫线的上游影响归入T1其他材料，未与主面料阶段重复相加。 生产端重点是电力、蒸汽以及聚酯原料，使用端重点是洗涤用电和清洁剂。减少非必要洗涤、提高洗衣装载率、自然晾干，以及降低生产电耗和蒸汽需求，均可能减排。 不确定性1：使用假设为100次混洗，每桶2.55kg、57kg水、0.5kWh电和0.05kg清洁剂，按质量分摊。若洗涤50次或150次，其余参数不变，总量分别为 9.41 与 16.55 kg CO2e。所以，作为单因素的情景，这里不能视为统计置信区间。 不确定性2：再生纤维采用浙江再生PET粒料加加工电力的组合代理，收率95%、电耗1.5kWh/kg；但是没有掌握具体纺丝技术和辅料。电耗0.75至3kWh/kg时，总量为 12.84 至 13.27 kg CO2e。 不确定性3：染料、助剂、清洁剂及部分辅料使用类别代理，RoW/GLO数据不一定代表中国的实际供应链。NaOH与NaClO基准按有效物质质量，若原数据是商品溶液则会高估用量。生产用水量未给、无法另外估算；T2污水直接排放和部分设施缺数据，可能低估数据。材料改用生产过程并另计模板运输，保留了背景上游物流。 质量口径假设：把0.310kg材料量视为含损耗毛投入，减少0.055kg边角料，净重0.255kg，报废回收0.03825kg、焚烧0.21675kg。该口径没有进行实测核实。保留原模板0.310kg的名义质量、仅调整洗涤和报废时，总量为 14.62 kg CO2e；生产清单保持不变。回收按cut-off移交，不能保证避免原生料可信，计算结果上零负担，但不代表着现实回收零排放。
A28: 阶段（互斥分解） | B28: kg CO2e/件 | C28: 占比
A29: T3 主面料内含纱线 | B29: =T3_纱线!H11*T2_面料!D2*T1_成衣!D2 -> 1.7208287 | C29: =B29/$B$4 -> 0.13256245
A30: T2 主面料加工 | B30: =(T2_面料!H19-T2_面料!H2)*T1_成衣!D2 -> 2.5245208 | C30: =B30/$B$4 -> 0.19447413
A31: T1 成衣与其他材料 | B31: =SUM(T1_成衣!H3:H14) -> 0.93011837 | C31: =B31/$B$4 -> 0.071650809
A32: 产品运输 | B32: =T1_成衣!H15 -> 0.12124875 | C32: =B32/$B$4 -> 0.0093402855
A33: 销售 | B33: =T1_成衣!H16 -> 0.084737294 | C33: =B33/$B$4 -> 0.0065276591
A34: 使用维护 | B34: =SUM(T1_成衣!H17:H20) -> 7.1395285 | C34: =B34/$B$4 -> 0.54998698
A35: 服装与包装报废 | B35: =SUM(T1_成衣!H21:H22,T1_成衣!H26:H27) -> 0.46028586 | C35: =B35/$B$4 -> 0.035457696
A36: 分阶段合计 | B36: =SUM(B29:B35) -> 12.981268 | C36: =SUM(C29:C35) -> 1
A37: 合计与成衣结果差额 | B37: =B36-B4 -> 0
A40: 洗涤次数敏感性 | B40: 次数 | C40: 全生命周期kg CO2e | D40: 相对基准变化
A41: =IF(B41=环境影响因子查询表!$B$35,"当前基准","洗涤次数情景") -> 洗涤次数情景 | B41: 50 | C41: =$B$4+(B41-环境影响因子查询表!$B$35)/环境影响因子查询表!$B$35*$B$34 -> 9.411504 | D41: =C41/$B$4-1 -> -0.27499349
A42: =IF(B42=环境影响因子查询表!$B$35,"当前基准","洗涤次数情景") -> 当前基准 | B42: 100 | C42: =$B$4+(B42-环境影响因子查询表!$B$35)/环境影响因子查询表!$B$35*$B$34 -> 12.981268 | D42: =C42/$B$4-1 -> 0
A43: =IF(B43=环境影响因子查询表!$B$35,"当前基准","洗涤次数情景") -> 洗涤次数情景 | B43: 150 | C43: =$B$4+(B43-环境影响因子查询表!$B$35)/环境影响因子查询表!$B$35*$B$34 -> 16.551033 | D43: =C43/$B$4-1 -> 0.27499349
A46: 再生纤维加工电耗敏感性
A47: 加工电耗kWh/kg纤维 | B47: 全生命周期kg CO2e | C47: 相对基准变化 | D47: 备注
A48: 0.75 | B48: =$B$4+(A48-环境影响因子查询表!$B$42)*环境影响因子查询表!$G$7*T3_纱线!D2*((T1_成衣!D2+T1_成衣!D3)*T2_面料!D2+T1_成衣!D4) -> 12.837423 | C48: =B48/$B$4-1 -> -0.011081001 | D48: 其余参数保持基准
A49: 1.5 | B49: =$B$4+(A49-环境影响因子查询表!$B$42)*环境影响因子查询表!$G$7*T3_纱线!D2*((T1_成衣!D2+T1_成衣!D3)*T2_面料!D2+T1_成衣!D4) -> 12.981268 | C49: =B49/$B$4-1 -> 0 | D49: 其余参数保持基准
A50: 3 | B50: =$B$4+(A50-环境影响因子查询表!$B$42)*环境影响因子查询表!$G$7*T3_纱线!D2*((T1_成衣!D2+T1_成衣!D3)*T2_面料!D2+T1_成衣!D4) -> 13.268959 | C50: =B50/$B$4-1 -> 0.022162001 | D50: 其余参数保持基准
A52: 成衣名义质量口径敏感性
A54: 情景 | B54: 名义质量kg/件 | C54: 全生命周期kg CO2e | D54: 说明
A55: 保留原模板报废总质量 | B55: =T1_成衣!D30 -> 0.31 | C55: =$B$4+(B55-T1_成衣!D29)*($B$34/T1_成衣!D29+(1-环境影响因子查询表!$B$40)*环境影响因子查询表!$G$26+环境影响因子查询表!$B$40*环境影响因子查询表!$G$9) -> 14.61777 | D55: 生产活动固定，仅变洗涤分摊与报废量
